Workbook

Sheet Cómo usar esto
B2: Iron Savage — datos pendientes para pasar a producción
B4: Qué es | C4: Todo lo que la tienda tiene todavía como dato de plantilla o provisional y hay que sustituir por datos reales antes de abrir al público: datos de la empresa, facturación, dominios, emails, pagos, envíos, textos, imágenes y decisiones de negocio.
B5: Qué hay que rellenar | C5: En la hoja «Datos a rellenar», la columna amarilla «VALOR REAL (a rellenar)» y la columna «Estado». Si algo no aplica, escribir «No aplica» y marcar el estado.
B6: Prioridad | C6: Crítico = sin esto no se puede abrir la tienda (o hay riesgo legal/fiscal). Importante = debería estar el día del lanzamiento. Recomendado = mejora, puede ir después. Informativo = solo para conocimiento.
B7: ¿Quién lo aporta? | C7: Cliente, Gestoría / asesor fiscal, Abogado, Banco o Técnico (el desarrollador). «Cliente + Técnico» = se decide juntos.
B8: Formato o ejemplo | C8: Cómo debe ser el dato. Los ejemplos son inventados: no copiarlos tal cual.
B9: Valor actual (plantilla) | C9: Lo que hay ahora en el proyecto. Casi siempre es un valor de pruebas.
B10: Dónde va | C10: Para el desarrollador: archivo o variable exacta donde se pondrá el dato. «.env.prod» = archivo de configuración del servidor de producción. «Dashboard» = se configura desde el panel de administración, sin programar.
B11: Datos confidenciales | C11: Contraseñas y claves (SMTP, Redsys, administrador) NO se escriben en este Excel: entregarlas por un canal seguro (gestor de contraseñas o en persona).
B12: Otras hojas | C12: «Textos de emails»: asunto y frases de cada email automático, para revisar o reescribir. «Resumen»: recuento automático por prioridad y estado. «Hosting»: requisitos del servidor y proveedores orientativos.
B13: Sustituye a | C13: Este archivo sustituye a «Checklist-Puesta-en-Produccion.xlsx», que quedó desactualizado.
B15: Leyenda
C16: Celda para rellenar por el cliente
C17: Fila de ejemplo (formato esperado)
C18: Prioridad: Crítico
C19: Prioridad: Importante
C20: Prioridad: Recomendado
C21: Prioridad: Informativo

Sheet Resumen
A1: Resumen de datos pendientes
A2: Se actualiza solo al cambiar la columna «Estado» de la hoja «Datos a rellenar» (excluye la fila de ejemplo).
A4: Prioridad | B4: Total | C4: Pendiente | D4: En curso | E4: Hecho | F4: No aplica | G4: % resuelto
A5: Crítico | B5: =COUNTIFS('Datos a rellenar'!$F$3:$F$119,$A5) | C5: =COUNTIFS('Datos a rellenar'!$F$3:$F$119,$A5,'Datos a rellenar'!$J$3:$J$119,"Pendiente") | D5: =COUNTIFS('Datos a rellenar'!$F$3:$F$119,$A5,'Datos a rellenar'!$J$3:$J$119,"En curso") | E5: =COUNTIFS('Datos a rellenar'!$F$3:$F$119,$A5,'Datos a rellenar'!$J$3:$J$119,"Hecho") | F5: =COUNTIFS('Datos a rellenar'!$F$3:$F$119,$A5,'Datos a rellenar'!$J$3:$J$119,"No aplica") | G5: =IF(B5=0,0,(E5+F5)/B5)
A6: Importante | B6: =COUNTIFS('Datos a rellenar'!$F$3:$F$119,$A6) | C6: =COUNTIFS('Datos a rellenar'!$F$3:$F$119,$A6,'Datos a rellenar'!$J$3:$J$119,"Pendiente") | D6: =COUNTIFS('Datos a rellenar'!$F$3:$F$119,$A6,'Datos a rellenar'!$J$3:$J$119,"En curso") | E6: =COUNTIFS('Datos a rellenar'!$F$3:$F$119,$A6,'Datos a rellenar'!$J$3:$J$119,"Hecho") | F6: =COUNTIFS('Datos a rellenar'!$F$3:$F$119,$A6,'Datos a rellenar'!$J$3:$J$119,"No aplica") | G6: =IF(B6=0,0,(E6+F6)/B6)
A7: Recomendado | B7: =COUNTIFS('Datos a rellenar'!$F$3:$F$119,$A7) | C7: =COUNTIFS('Datos a rellenar'!$F$3:$F$119,$A7,'Datos a rellenar'!$J$3:$J$119,"Pendiente") | D7: =COUNTIFS('Datos a rellenar'!$F$3:$F$119,$A7,'Datos a rellenar'!$J$3:$J$119,"En curso") | E7: =COUNTIFS('Datos a rellenar'!$F$3:$F$119,$A7,'Datos a rellenar'!$J$3:$J$119,"Hecho") | F7: =COUNTIFS('Datos a rellenar'!$F$3:$F$119,$A7,'Datos a rellenar'!$J$3:$J$119,"No aplica") | G7: =IF(B7=0,0,(E7+F7)/B7)
A8: Informativo | B8: =COUNTIFS('Datos a rellenar'!$F$3:$F$119,$A8) | C8: =COUNTIFS('Datos a rellenar'!$F$3:$F$119,$A8,'Datos a rellenar'!$J$3:$J$119,"Pendiente") | D8: =COUNTIFS('Datos a rellenar'!$F$3:$F$119,$A8,'Datos a rellenar'!$J$3:$J$119,"En curso") | E8: =COUNTIFS('Datos a rellenar'!$F$3:$F$119,$A8,'Datos a rellenar'!$J$3:$J$119,"Hecho") | F8: =COUNTIFS('Datos a rellenar'!$F$3:$F$119,$A8,'Datos a rellenar'!$J$3:$J$119,"No aplica") | G8: =IF(B8=0,0,(E8+F8)/B8)
A9: TOTAL | B9: =SUM(B5:B8) | C9: =SUM(C5:C8) | D9: =SUM(D5:D8) | E9: =SUM(E5:E8) | F9: =SUM(F5:F8) | G9: =IF(B9=0,0,(E9+F9)/B9)
A11: Pendientes por área
A12: Área | B12: Total | C12: Pendiente | D12: Críticos pendientes
A13: Empresa y datos legales | B13: =COUNTIFS('Datos a rellenar'!$B$3:$B$119,$A13) | C13: =COUNTIFS('Datos a rellenar'!$B$3:$B$119,$A13,'Datos a rellenar'!$J$3:$J$119,"Pendiente") | D13: =COUNTIFS('Datos a rellenar'!$B$3:$B$119,$A13,'Datos a rellenar'!$J$3:$J$119,"Pendiente",'Datos a rellenar'!$F$3:$F$119,"Crítico")
A14: Textos legales: decisiones y revisión | B14: =COUNTIFS('Datos a rellenar'!$B$3:$B$119,$A14) | C14: =COUNTIFS('Datos a rellenar'!$B$3:$B$119,$A14,'Datos a rellenar'!$J$3:$J$119,"Pendiente") | D14: =COUNTIFS('Datos a rellenar'!$B$3:$B$119,$A14,'Datos a rellenar'!$J$3:$J$119,"Pendiente",'Datos a rellenar'!$F$3:$F$119,"Crítico")
A15: Facturación y fiscalidad | B15: =COUNTIFS('Datos a rellenar'!$B$3:$B$119,$A15) | C15: =COUNTIFS('Datos a rellenar'!$B$3:$B$119,$A15,'Datos a rellenar'!$J$3:$J$119,"Pendiente") | D15: =COUNTIFS('Datos a rellenar'!$B$3:$B$119,$A15,'Datos a rellenar'!$J$3:$J$119,"Pendiente",'Datos a rellenar'!$F$3:$F$119,"Crítico")
A16: Dominios, servidor y despliegue | B16: =COUNTIFS('Datos a rellenar'!$B$3:$B$119,$A16) | C16: =COUNTIFS('Datos a rellenar'!$B$3:$B$119,$A16,'Datos a rellenar'!$J$3:$J$119,"Pendiente") | D16: =COUNTIFS('Datos a rellenar'!$B$3:$B$119,$A16,'Datos a rellenar'!$J$3:$J$119,"Pendiente",'Datos a rellenar'!$F$3:$F$119,"Crítico")
A17: Correo electrónico (emails automáticos) | B17: =COUNTIFS('Datos a rellenar'!$B$3:$B$119,$A17) | C17: =COUNTIFS('Datos a rellenar'!$B$3:$B$119,$A17,'Datos a rellenar'!$J$3:$J$119,"Pendiente") | D17: =COUNTIFS('Datos a rellenar'!$B$3:$B$119,$A17,'Datos a rellenar'!$J$3:$J$119,"Pendiente",'Datos a rellenar'!$F$3:$F$119,"Crítico")
A18: Pagos con tarjeta (Redsys) | B18: =COUNTIFS('Datos a rellenar'!$B$3:$B$119,$A18) | C18: =COUNTIFS('Datos a rellenar'!$B$3:$B$119,$A18,'Datos a rellenar'!$J$3:$J$119,"Pendiente") | D18: =COUNTIFS('Datos a rellenar'!$B$3:$B$119,$A18,'Datos a rellenar'!$J$3:$J$119,"Pendiente",'Datos a rellenar'!$F$3:$F$119,"Crítico")
A19: Accesos y claves internas | B19: =COUNTIFS('Datos a rellenar'!$B$3:$B$119,$A19) | C19: =COUNTIFS('Datos a rellenar'!$B$3:$B$119,$A19,'Datos a rellenar'!$J$3:$J$119,"Pendiente") | D19: =COUNTIFS('Datos a rellenar'!$B$3:$B$119,$A19,'Datos a rellenar'!$J$3:$J$119,"Pendiente",'Datos a rellenar'!$F$3:$F$119,"Crítico")
A20: Envíos y logística | B20: =COUNTIFS('Datos a rellenar'!$B$3:$B$119,$A20) | C20: =COUNTIFS('Datos a rellenar'!$B$3:$B$119,$A20,'Datos a rellenar'!$J$3:$J$119,"Pendiente") | D20: =COUNTIFS('Datos a rellenar'!$B$3:$B$119,$A20,'Datos a rellenar'!$J$3:$J$119,"Pendiente",'Datos a rellenar'!$F$3:$F$119,"Crítico")
A21: Textos de la tienda (marketing) | B21: =COUNTIFS('Datos a rellenar'!$B$3:$B$119,$A21) | C21: =COUNTIFS('Datos a rellenar'!$B$3:$B$119,$A21,'Datos a rellenar'!$J$3:$J$119,"Pendiente") | D21: =COUNTIFS('Datos a rellenar'!$B$3:$B$119,$A21,'Datos a rellenar'!$J$3:$J$119,"Pendiente",'Datos a rellenar'!$F$3:$F$119,"Crítico")
A22: Marca e imágenes | B22: =COUNTIFS('Datos a rellenar'!$B$3:$B$119,$A22) | C22: =COUNTIFS('Datos a rellenar'!$B$3:$B$119,$A22,'Datos a rellenar'!$J$3:$J$119,"Pendiente") | D22: =COUNTIFS('Datos a rellenar'!$B$3:$B$119,$A22,'Datos a rellenar'!$J$3:$J$119,"Pendiente",'Datos a rellenar'!$F$3:$F$119,"Crítico")
A23: Analítica (Google Analytics 4) | B23: =COUNTIFS('Datos a rellenar'!$B$3:$B$119,$A23) | C23: =COUNTIFS('Datos a rellenar'!$B$3:$B$119,$A23,'Datos a rellenar'!$J$3:$J$119,"Pendiente") | D23: =COUNTIFS('Datos a rellenar'!$B$3:$B$119,$A23,'Datos a rellenar'!$J$3:$J$119,"Pendiente",'Datos a rellenar'!$F$3:$F$119,"Crítico")
A24: Catálogo y contenido | B24: =COUNTIFS('Datos a rellenar'!$B$3:$B$119,$A24) | C24: =COUNTIFS('Datos a rellenar'!$B$3:$B$119,$A24,'Datos a rellenar'!$J$3:$J$119,"Pendiente") | D24: =COUNTIFS('Datos a rellenar'!$B$3:$B$119,$A24,'Datos a rellenar'!$J$3:$J$119,"Pendiente",'Datos a rellenar'!$F$3:$F$119,"Crítico")
... A26: Copias de seguridad | B26: =COUNTIFS('Datos a rellenar'!$B$3:$B$119,$A26) | C26: =COUNTIFS('Datos a rellenar'!$B$3:$B$119,$A26,'Datos a rellenar'!$J$3:$J$119,"Pendiente") | D26: =COUNTIFS('Datos a rellenar'!$B$3:$B$119,$A26,'Datos a rellenar'!$J$3:$J$119,"Pendiente",'Datos a rellenar'!$F$3:$F$119,"Crítico")

Sheet Datos a rellenar
A1: Nº | B1: Área | C1: Qué se necesita | D1: Para qué sirve / explicación | E1: Formato o ejemplo esperado | F1: Prioridad | G1: Valor actual (plantilla) | H1: ¿Quién lo aporta? | I1: VALOR REAL (a rellenar) | J1: Estado | K1: Dónde va (para el técnico) | L1: Notas
A2: Ej. | B2: (ejemplo) | C2: Email de atención al cliente | D2: Dirección donde escriben los clientes. | E2: hola@ironsavage.es | F2: Crítico | G2: [EMAIL DE ATENCIÓN AL CLIENTE] | H2: Cliente | I2: hola@ironsavage.es | J2: Hecho | K2: apps/storefront/src/config/company.ts → COMPANY.contactEmail | L2: Fila de ejemplo: no forma parte de la lista.
B3: A. Empresa y datos legales
A4: 1 | B4: Empresa y datos legales | C4: Razón social o nombre del titular | D4: Nombre legal exacto de quien vende. Aparece en el aviso legal, la privacidad, los términos, envíos y devoluciones, accesibilidad, IA y en el aviso de privacidad del registro. | E4: Iron Savage Nutrition, S.L. (o nombre y apellidos si es autónomo) | F4: Crítico | G4: [RAZÓN SOCIAL O NOMBRE DEL TITULAR] resaltado en amarillo en la web | H4: Cliente | J4: Pendiente | K4: apps/storefront/src/config/company.ts → COMPANY.legalName | L4: Se rellena una vez y cambia en todas las páginas.
A5: 2 | B5: Empresa y datos legales | C5: NIF / CIF | D5: Identificación fiscal del titular (obligatoria en el aviso legal, LSSI-CE art. 10). | E5: B12345678 | F5: Crítico | G5: [NIF/CIF] | H5: Cliente | J5: Pendiente | K5: apps/storefront/src/config/company.ts → COMPANY.taxId
A6: 3 | B6: Empresa y datos legales | C6: Domicilio social | D6: Dirección registrada del titular. | E6: Calle Mayor 1, 2º B, 28013 Madrid | F6: Crítico | G6: [DOMICILIO SOCIAL COMPLETO] | H6: Cliente | J6: Pendiente | K6: apps/storefront/src/config/company.ts → COMPANY.address | L6: También se usa como dirección postal para reclamaciones y derechos RGPD.
A7: 4 | B7: Empresa y datos legales | C7: Datos del Registro Mercantil | D7: Obligatorio si es una sociedad (S.L., S.A.). Si es autónomo, no aplica. | E7: Inscrita en el Registro Mercantil de Madrid, Tomo 1234, Folio 56, Hoja M-78901 | F7: Crítico | G7: [DATOS REGISTRALES…] | H7: Cliente | J7: Pendiente | K7: apps/storefront/src/config/company.ts → COMPANY.registry | L7: Poner «No aplica» si es autónomo.
A8: 5 | B8: Empresa y datos legales | C8: Email de atención al cliente | D8: Dirección donde escriben los clientes (dudas, devoluciones, reclamaciones, accesibilidad). | E8: hola@ironsavage.es | F8: Crítico | G8: [EMAIL DE ATENCIÓN AL CLIENTE] | H8: Cliente | J8: Pendiente | K8: apps/storefront/src/config/company.ts → COMPANY.contactEmail | L8: Debe ser un buzón que alguien lea.
A9: 6 | B9: Empresa y datos legales | C9: Email de protección de datos | D9: Para ejercer derechos RGPD (acceso, supresión…). Puede ser el mismo que el de atención al cliente. | E9: privacidad@ironsavage.es | F9: Crítico | G9: [EMAIL DE PROTECCIÓN DE DATOS] | H9: Cliente | J9: Pendiente | K9: apps/storefront/src/config/company.ts → COMPANY.privacyEmail
A10: 7 | B10: Empresa y datos legales | C10: Teléfono de contacto | D10: La ley exige un medio de contacto directo y efectivo; el teléfono es lo habitual. | E10: +34 600 000 000 | F10: Importante | G10: [TELÉFONO DE CONTACTO] | H10: Cliente | J10: Pendiente | K10: apps/storefront/src/config/company.ts → COMPANY.phone
A11: 8 | B11: Empresa y datos legales | C11: Registro sanitario (RGSEAA) o comunicación | D11: Las empresas que comercializan complementos alimenticios deben estar inscritas o haber comunicado su actividad a Sanidad. | E11: Nº RGSEAA 26.012345/M (o «No aplica») | F11: Importante | G11: [Nº DE REGISTRO SANITARIO…] | H11: Cliente | J11: Pendiente | K11: apps/storefront/src/config/company.ts → COMPANY.healthRegistry | L11: Confirmar con un consultor sanitario si aplica.
A12: 9 | B12: Empresa y datos legales | C12: Delegado de protección de datos (DPD) | D12: Solo obligatorio en algunos casos. Si no se ha designado, indicarlo. | E12: No designado (o nombre + email) | F12: Recomendado | G12: [DELEGADO DE PROTECCIÓN DE DATOS…] | H12: Cliente | J12: Pendiente | K12: apps/storefront/src/config/company.ts → COMPANY.dpo
A13: 10 | B13: Empresa y datos legales | C13: Proveedor de hosting y país | D13: Aparece como destinatario de datos en la política de privacidad. | E13: Hetzner Online GmbH (Alemania) | F13: Importante | G13: [PROVEEDOR DE HOSTING Y PAÍS] | H13: Cliente + Técnico | J13: Pendiente | K13: apps/storefront/src/config/company.ts → COMPANY.hostingProvider | L13: Se decide al contratar el servidor (hoja «Hosting»).
A14: 11 | B14: Empresa y datos legales | C14: Proveedor de envío de emails y país | D14: Aparece como destinatario de datos en la política de privacidad. | E14: Brevo (Francia) | F14: Importante | G14: [PROVEEDOR DE ENVÍO DE EMAILS Y PAÍS] | H14: Cliente + Técnico | J14: Pendiente | K14: apps/storefront/src/config/company.ts → COMPANY.emailProvider | L14: Ver sección E.
A15: 12 | B15: Empresa y datos legales | C15: Empresas de transporte | D15: Aparecen en la política de privacidad y en envíos y devoluciones. | E15: Correos Express y SEUR | F15: Importante | G15: [EMPRESAS DE TRANSPORTE] | H15: Cliente | J15: Pendiente | K15: apps/storefront/src/config/company.ts → COMPANY.carriers
A16: 13 | B16: Empresa y datos legales | C16: Dirección para devoluciones | D16: A dónde envía el cliente los productos devueltos. | E16: Almacén Iron Savage, Pol. Ind. X, nave 3, 28906 Getafe (Madrid) | F16: Crítico | G16: [DIRECCIÓN PARA DEVOLUCIONES] | H16: Cliente | J16: Pendiente | K16: apps/storefront/src/config/company.ts → COMPANY.returnsAddress | L16: Puede coincidir con el domicilio social.
A17: 14 | B17: Empresa y datos legales | C17: Plazos de entrega | D17: Plazo estimado desde que se confirma el pago (se muestra en envíos y devoluciones). | E17: 24-72 h laborables en península; 3-5 días laborables en Baleares | F17: Crítico | G17: [PLAZOS DE ENTREGA] | H17: Cliente | J17: Pendiente | K17: apps/storefront/src/config/company.ts → COMPANY.deliveryTimes | L17: Nunca más de 30 días (límite legal).
A18: 15 | B18: Empresa y datos legales | C18: Quién paga la devolución por desistimiento | D18: La ley obliga a informar de quién asume el coste; si no se informa, lo paga la tienda. | E18: El cliente, con un coste aproximado de 5 € (o «Gratuita») | F18: Crítico | G18: [QUIÉN ASUME EL COSTE DE LA DEVOLUCIÓN] | H18: Cliente | J18: Pendiente | K18: apps/storefront/src/config/company.ts → COMPANY.returnCosts
A19: 16 | B19: Empresa y datos legales | C19: Entidad de resolución de conflictos / arbitraje de consumo | D19: Hay que informar si la empresa está adherida a alguna (o que no lo está). | E19: No estamos adheridos a ningún sistema de resolución alternativa (o «Junta Arbitral de Consumo de …») | F19: Importante | G19: [ENTIDAD DE RESOLUCIÓN ALTERNATIVA…] | H19: Cliente | J19: Pendiente | K19: apps/storefront/src/config/company.ts → COMPANY.adrEntity
B20: B. Textos legales: decisiones y revisión
A21: 17 | B21: Textos legales: decisiones y revisión | C21: Revisión de los textos legales por un abogado | D21: Aviso legal, términos, privacidad, cookies, envíos y devoluciones, IA y accesibilidad están redactados conforme a la normativa española, pero deben revisarse antes de publicar. | E21: OK del abogado (fecha) | F21: Crítico | G21: Borrador con aviso «pendiente de revisión legal» | H21: Abogado | J21: Pendiente | K21: apps/storefront/src/site/legal/*.tsx
A22: 18 | B22: Textos legales: decisiones y revisión | C22: Edad mínima para crear una cuenta | D22: Los términos dicen hoy «mayor de 18 años». | E22: 18 años (o la que decida el cliente; nunca menos de 14 por RGPD) | F22: Importante | G22: 18 años | H22: Cliente | J22: Pendiente | K22: terminos-y-condiciones.tsx §3 y politica-de-privacidad.tsx
A23: 19 | B23: Textos legales: decisiones y revisión | C23: Qué contenidos se han creado con IA | D23: Transparencia exigida: indicar si textos, imágenes o traducciones de la tienda se han generado con IA. | E23: Descripciones de producto redactadas con IA y revisadas por el equipo; imágenes: ninguna | F23: Importante | G23: [INDICAR QUÉ CONTENIDOS SE HAN GENERADO CON IA…] | H23: Cliente | J23: Pendiente | K23: apps/storefront/src/site/legal/uso-de-inteligencia-artificial.tsx
A24: 20 | B24: Textos legales: decisiones y revisión | C24: ¿La empresa es microempresa? | D24: Menos de 10 empleados y facturación ≤ 2 M€: queda exenta de la Ley 11/2023 de accesibilidad (la tienda ya cumple igualmente). | E24: Sí / No | F24: Informativo | G24: — | H24: Cliente | J24: Pendiente | K24: docs/legal.md (accesibilidad) | L24: Solo informativo; la declaración de accesibilidad ya está publicada.
A25: 21 | B25: Textos legales: decisiones y revisión | C25: Barreras de accesibilidad conocidas | D25: Si una revisión manual (lector de pantalla) detecta problemas, se anotan en la declaración con su alternativa. | E25: Ninguna conocida (o lista de barreras + fecha de solución) | F25: Recomendado | G25: [AÑADIR AQUÍ LAS BARRERAS…] | H25: Cliente + Técnico | J25: Pendiente | K25: apps/storefront/src/site/legal/accesibilidad.tsx
A26: 22 | B26: Textos legales: decisiones y revisión | C26: ¿Se enviarán newsletters / comunicaciones comerciales? | D26: La privacidad contempla esta posibilidad, pero hoy la tienda no tiene newsletter ni casilla para suscribirse. | E26: No por ahora (o «Sí» → hay que desarrollar la suscripción con consentimiento) | F26: Recomendado | G26: No existe | H26: Cliente | J26: Pendiente | K26: — | L26: Si es «Sí», requiere desarrollo.
A27: 23 | B27: Textos legales: decisiones y revisión | C27: Hojas oficiales de queja y reclamación | D27: Obligatorio tenerlas a disposición del consumidor; el modelo depende de la comunidad autónoma. | E27: Modelo oficial de la Comunidad de Madrid, en PDF | F27: Importante | G27: Los términos indican que se solicitan por email | H27: Cliente | J27: Pendiente | K27: —
A28: 24 | B28: Textos legales: decisiones y revisión | C28: Excepciones al desistimiento | D28: Los textos excluyen del desistimiento los productos con el precinto abierto (salud e higiene). Confirmar que aplica a todo el catálogo. | E28: Confirmado / cambios | F28: Importante | G28: Productos desprecintados excluidos | H28: Abogado | J28: Pendiente | K28: terminos-y-condiciones.tsx §9 y envios-y-devoluciones.tsx §3
A29: 25 | B29: Textos legales: decisiones y revisión | C29: Quitar el aviso «Borrador — pendiente de revisión legal» | D29: Cuando no quede ningún dato resaltado y el abogado haya dado el visto bueno. | E29: Hecho | F29: Crítico | G29: Visible en todas las páginas legales | H29: Técnico | J29: Pendiente | K29: apps/storefront/src/site/legal/legal-page.tsx
A30: 26 | B30: Textos legales: decisiones y revisión | C30: Versión (fecha) de los textos legales | D30: Fecha de «Última actualización» y versión que se guarda en cada pedido al aceptar los términos. | E30: 2026-10-15 | F30: Informativo | G30: 2026-09-28 | H30: Técnico | J30: Pendiente | K30: apps/storefront/src/config/legal.ts → LEGAL_VERSION | L30: Actualizar cada vez que cambie un texto legal.
B31: C. Facturación y fiscalidad
A32: 27 | B32: Facturación y fiscalidad | C32: Razón social en las facturas | D32: Nombre fiscal exacto del emisor de la factura. | E32: Iron Savage Nutrition, S.L. | F32: Crítico | G32: Tienda Suple (placeholder) | H32: Cliente | J32: Pendiente | K32: .env.prod → INVOICE_STORE_NAME | L32: Si no se rellena, las facturas dicen «Razón social pendiente de configurar».
A33: 28 | B33: Facturación y fiscalidad | C33: NIF/CIF en las facturas | E33: B12345678 | F33: Crítico | G33: B00000000 | H33: Cliente | J33: Pendiente | K33: .env.prod → INVOICE_STORE_TAX_ID
A34: 29 | B34: Facturación y fiscalidad | C34: Dirección fiscal en las facturas | E34: Calle Mayor 1, 2º B, 28013 Madrid, España | F34: Crítico | G34: Calle Ejemplo 1, 28001 Madrid, España | H34: Cliente | J34: Pendiente | K34: .env.prod → INVOICE_STORE_ADDRESS
A35: 30 | B35: Facturación y fiscalidad | C35: Email en las facturas | E35: facturacion@ironsavage.es | F35: Importante | G35: facturacion@example.com | H35: Cliente | J35: Pendiente | K35: .env.prod → INVOICE_STORE_EMAIL
A36: 31 | B36: Facturación y fiscalidad | C36: Teléfono en las facturas (opcional) | D36: Solo aparece si se rellena. | E36: +34 600 000 000 | F36: Recomendado | G36: (vacío) | H36: Cliente | J36: Pendiente | K36: .env.prod → INVOICE_STORE_PHONE
A37: 32 | B37: Facturación y fiscalidad | C37: Datos del Registro Mercantil en las facturas | D37: Obligatorio en las facturas de una sociedad (art. 24 del Reglamento del Registro Mercantil). | E37: Inscrita en el R.M. de Madrid, Tomo 1234, Folio 56, Hoja M-78901 | F37: Crítico | G37: (vacío) | H37: Cliente | J37: Pendiente | K37: .env.prod → INVOICE_STORE_REGISTRY | L37: Dejar vacío si es autónomo.
A38: 33 | B38: Facturación y fiscalidad | C38: Tipo de IVA de los productos | D38: Ya están creadas las categorías General 21 %, Reducido 10 % y Superreducido 4 %. Falta decidir cuál lleva cada producto; por defecto, General. Los complementos alimenticios suelen tributar al 10 %. | E38: Proteínas y creatinas: Reducido (10 %); shakers y ropa: General (21 %) | F38: Crítico | G38: General 21 % para todo (categorías 10 % y 4 % ya disponibles) | H38: Gestoría / asesor fiscal | J38: Pendiente | K38: Dashboard → Catálogo → producto → variante → Categoría de impuesto | L38: Afecta al precio final y a las facturas. Ver docs/iva-envios-facturacion.md.
A39: 34 | B39: Facturación y fiscalidad | C39: ¿Se vende a Canarias, Ceuta y Melilla? | D39: Ya está preparado: esos pedidos se detectan por código postal y van sin IVA español (zona «Canarias, Ceuta y Melilla»). Hoy no se puede comprar desde allí hasta que se marque el territorio en un método de envío. | E39: No / Sí → marcar «Islas Canarias» (etc.) en un método de envío con su tarifa | F39: Importante | G39: No se envía (preparado) | H39: Gestoría / asesor fiscal | J39: Pendiente | K39: Dashboard → Ajustes → Métodos de envío → condición «Territorios de España y pedido mínimo» | L39: Confirmar también la mención de exención que imprime la factura (fila siguiente).
A40: 35 | B40: Facturación y fiscalidad | C40: Mención de exención en facturas a Canarias, Ceuta y Melilla | D40: Las facturas con líneas al 0 % imprimen: «Operación exenta de IVA (art. 21 de la Ley 37/1992): entrega de bienes con destino a Canarias, Ceuta o Melilla». | E40: Texto confirmado o corregido | F40: Importante | G40: Texto provisional | H40: Gestoría / asesor fiscal | J40: Pendiente | K40: apps/server/src/plugins/invoicing/invoice-pdf.generator.ts
...

Sheet Textos de emails
A1: Email | B1: Cuándo se envía | C1: Asunto actual | D1: Frases clave actuales | E1: Qué conviene revisar | F1: TEXTO NUEVO (opcional) | G1: Archivo (apps/server/src/plugins/transactional-email/)
A2: Verifica tu email | B2: Al registrarse en la tienda | C2: Verifica tu email en {tienda} | D2: Gracias por registrarte en {tienda}. Confirma tu dirección de email para activar tu cuenta. | E2: Tono y texto del botón. | G2: templates/email-verification.ts
A3: Activa tu cuenta | B3: Cuando un administrador crea la cuenta de un cliente o atleta | C3: Activa tu cuenta en {tienda} | D3: Te hemos creado una cuenta en {tienda}. Para activarla, confirma tu email y elige tu contraseña. | E3: Tono. | G3: templates/email-verification.ts
A4: Bienvenida | B4: Al verificar la cuenta | C4: Bienvenido/a a {tienda} | D4: Tu cuenta en {tienda} ha sido verificada correctamente. ¡Ya puedes comprar con tu cuenta! · Gracias por registrarte. | E4: Se puede añadir un mensaje de bienvenida o un cupón de primera compra. | G4: templates/registration-confirmation.ts
A5: Recupera tu contraseña | B5: Al pedir «He olvidado mi contraseña» | C5: Recupera tu contraseña en {tienda} | D5: Hemos recibido una solicitud para restablecer la contraseña de tu cuenta en {tienda}. | E5: Tono. | G5: templates/password-reset.ts
A6: Crea tu contraseña | B6: Cuando un administrador verifica una cuenta y envía el enlace | C6: Crea tu contraseña en {tienda} | D6: Tu cuenta en {tienda} ya está activa. Solo falta que elijas tu contraseña para poder iniciar sesión. | E6: Tono. | G6: templates/password-reset.ts
A7: Pedido recibido | B7: Al iniciar el pago | C7: Hemos recibido tu pedido #CÓDIGO | D7: Hemos recibido tu pedido… (con el resumen de productos) | E7: Tono. | G7: templates/order-received.ts
A8: Pago confirmado | B8: Cuando Redsys confirma el cobro | C8: Pago confirmado — pedido #CÓDIGO | D8: Hemos confirmado el pago de tu pedido… Prepararemos tu pedido para el envío en breve. | E8: Poner un plazo concreto de preparación/envío en lugar de «en breve». | G8: templates/payment-confirmed.ts
A9: Pedido cancelado | B9: Al cancelar un pedido desde el panel | C9: Pedido cancelado — #CÓDIGO | D9: Tu pedido … ha sido cancelado. Si crees que se trata de un error, contáctanos. | E9: Falta cómo contactar: añadir el email o el teléfono de atención al cliente. Indicar el plazo del reembolso. | G9: templates/order-cancelled.ts
A10: Factura disponible | B10: Al generarse la factura (pago confirmado) | C10: Factura A-000001 disponible | D10: Ya tienes disponible la factura… También puedes descargarla en cualquier momento desde tu cuenta. | E10: Tono. | G10: templates/invoice-available.ts
A11: Reenvío de factura | B11: Cuando un administrador reenvía la factura | C11: Factura A-000001 — pedido #CÓDIGO | D11: Te reenviamos la factura … correspondiente al pedido … La encontrarás adjunta a este email en PDF. | E11: Tono. | G11: templates/invoice-resend.ts
A12: Factura rectificativa | B12: Al liquidar un reembolso | C12: Factura rectificativa R-000001 — pedido #CÓDIGO | D12: Hemos tramitado un reembolso de tu pedido… Te adjuntamos la factura rectificativa…, que corrige la factura… por el importe reembolsado. | E12: Tono; plazo en que llega el dinero. | G12: templates/credit-note-available.ts
A13: Pie común de todos los emails | B13: En todos | C13: — | D13: {tienda} — este es un email transaccional automático, por favor no respondas si no tienes una duda relacionada. · Ir a la tienda · Mi cuenta · © {año} {tienda} | E13: La frase es confusa (¿se puede responder o no?): decidir según EMAIL_REPLY_TO. Recomendado añadir razón social, dirección y enlace a la política de privacidad. | G13: templates/layout.ts
A14: Pedido enviado (no existe) | B14: — | C14: — | D14: — | E14: Decidir si se quiere un email al enviar el pedido, con transportista y número de seguimiento (requiere desarrollo). | G14: —
A16: {tienda} = nombre comercial (EMAIL_STORE_NAME). #CÓDIGO = código del pedido. Todos los emails llevan el logo, los colores de la marca y enlaces a la tienda y a «Mi cuenta».

Sheet Hosting
B1: Dónde alojar la tienda — recomendaciones
B3: La aplicación son 4 piezas que corren juntas con Docker en un único servidor (ya preparado, ver docker-compose.prod.yml): base de datos (PostgreSQL), servidor Vendure (API + panel de administración), worker (tareas en segundo plano: emails, facturas...) y la tienda (Next.js) — más un proxy (Caddy) que da el certificado HTTPS gratis y automático. No hace falta contratar la base de datos por separado.
B5: Requisitos imprescindibles (no negociables)
B6: • Soporte para Docker y Docker Compose
B7: • IP pública fija, con capacidad de abrir los puertos 80 y 443
B8: • Almacenamiento persistente (volúmenes en disco) — las fotos de producto y las facturas en PDF se guardan en disco; se perderían en un hosting "sin estado" tipo serverless puro
B9: • Acceso administrador/SSH al servidor
B11: Specs mínimas recomendadas para el servidor
B12: Recurso | C12: Mínimo | D12: Recomendado (con margen) | E12: Notas
B13: CPU | C13: 2 vCPU | D13: 4 vCPU
B14: RAM | C14: 4 GB | D14: 8 GB
B15: Disco | C15: 40 GB SSD | D15: 80 GB SSD | E15: Crece con catálogo, facturas y backups
B16: Sistema operativo | C16: Linux (Ubuntu 22.04/24.04 LTS) + Docker | D16: Igual
B17: Red | C17: IP pública fija, puertos 80/443 abiertos | D17: Igual
B18: Ancho de banda | C18: Según tráfico esperado | D18: La mayoría de VPS incluyen varios TB/mes
B19: Snapshot del proveedor | C19: Opcional | D19: Recomendable, además del backup propio de la app
B21: Proveedores de servidor orientativos (ejemplos, sin compromiso)
B22: Proveedor | C22: Tipo | D22: Precio orientativo/mes | E22: Notas
B23: Hetzner Cloud | C23: VPS Europa | D23: 15-25 € | E23: Buena relación calidad-precio, datacenters en Alemania/Finlandia
B24: DigitalOcean | C24: VPS | D24: 24-48 $ | E24: Interfaz sencilla, buena documentación
B25: OVHcloud | C25: VPS Europa (España/Francia) | D25: 15-30 € | E25: Proveedor europeo, facturación en español
B26: Contabo | C26: VPS | D26: 10-20 € | E26: Más barato, algo menos de soporte
B27: AWS Lightsail / Google Cloud | C27: VPS gestionado | D27: Desde ~20 $ | E27: Más flexible para escalar más adelante, curva de aprendizaje mayor
B29: Almacenamiento externo para backups (recomendado, opcional)
B30: Proveedor | C30: Precio orientativo | D30: Notas
B31: Backblaze B2 | C31: ~5 $/TB/mes | D31: Barato, compatible con S3
B32: Amazon S3 | C32: Variable | D32: Estándar de la industria
B33: Wasabi | C33: ~7 $/TB/mes | D33: Sin coste de salida de datos
B35: Nota: si en el futuro crece mucho el volumen de pedidos, la base de datos se puede separar a un servicio gestionado (ej. Amazon RDS, DigitalOcean Managed Postgres) sin cambios grandes en el código — no hace falta decidirlo ahora.
